<?xml version="1.0" ?>
<sdf version="1.6">
  <world name="visual_servoing">
    <physics name="1ms" type="ignored">
      <max_step_size>0.001</max_step_size>
      <real_time_factor>1.0</real_time_factor>
    </physics>
    <plugin
      filename="ignition-gazebo-physics-system"
      name="gz::sim::systems::Physics">
    </plugin>
    <plugin
      filename="ignition-gazebo-sensors-system"
      name="gz::sim::systems::Sensors">
      <render_engine>ogre2</render_engine>
    </plugin>
    <plugin
      filename="ignition-gazebo-user-commands-system"
      name="ignition::gazebo::systems::UserCommands">
    </plugin>
    <plugin
      filename="ignition-gazebo-scene-broadcaster-system"
      name="gz::sim::systems::SceneBroadcaster">
    </plugin>

    <gui fullscreen="0">

      <!-- 3D scene -->
      <plugin filename="MinimalScene" name="3D View">
        <ignition-gui>
          <title>3D View</title>
          <property type="bool" key="showTitleBar">false</property>
          <property type="string" key="state">docked</property>
        </ignition-gui>

        <engine>ogre2</engine>
        <scene>scene</scene>
        <ambient_light>0.4 0.4 0.4</ambient_light>
        <background_color>0.8 0.8 0.8</background_color>
        <camera_pose>-6 0 6 0 0.5 0</camera_pose>
      </plugin>

      <!-- Plugins that add functionality to the scene -->
      <plugin filename="EntityContextMenuPlugin" name="Entity context menu">
        <ignition-gui>
          <property key="state" type="string">floating</property>
          <property key="width" type="double">5</property>
          <property key="height" type="double">5</property>
          <property key="showTitleBar" type="bool">false</property>
        </ignition-gui>
      </plugin>
      <plugin filename="GzSceneManager" name="Scene Manager">
        <ignition-gui>
          <property key="resizable" type="bool">false</property>
          <property key="width" type="double">5</property>
          <property key="height" type="double">5</property>
          <property key="state" type="string">floating</property>
          <property key="showTitleBar" type="bool">false</property>
        </ignition-gui>
      </plugin>
      <plugin filename="InteractiveViewControl" name="Interactive view control">
        <ignition-gui>
          <property key="resizable" type="bool">false</property>
          <property key="width" type="double">5</property>
          <property key="height" type="double">5</property>
          <property key="state" type="string">floating</property>
          <property key="showTitleBar" type="bool">false</property>
        </ignition-gui>
      </plugin>
      <plugin filename="CameraTracking" name="Camera Tracking">
        <ignition-gui>
          <property key="resizable" type="bool">false</property>
          <property key="width" type="double">5</property>
          <property key="height" type="double">5</property>
          <property key="state" type="string">floating</property>
          <property key="showTitleBar" type="bool">false</property>
        </ignition-gui>
      </plugin>
      <!-- World control -->
      <plugin filename="WorldControl" name="World control">
        <ignition-gui>
          <title>World control</title>
          <property type="bool" key="showTitleBar">false</property>
          <property type="bool" key="resizable">false</property>
          <property type="double" key="height">72</property>
          <property type="double" key="width">121</property>
          <property type="double" key="z">1</property>

          <property type="string" key="state">floating</property>
          <anchors target="3D View">
            <line own="left" target="left"/>
            <line own="bottom" target="bottom"/>
          </anchors>
        </ignition-gui>

        <play_pause>true</play_pause>
        <step>true</step>
        <start_paused>true</start_paused>
        <use_event>true</use_event>

      </plugin>

      <!-- World statistics -->
      <plugin filename="WorldStats" name="World stats">
        <ignition-gui>
          <title>World stats</title>
          <property type="bool" key="showTitleBar">false</property>
          <property type="bool" key="resizable">false</property>
          <property type="double" key="height">110</property>
          <property type="double" key="width">290</property>
          <property type="double" key="z">1</property>

          <property type="string" key="state">floating</property>
          <anchors target="3D View">
            <line own="right" target="right"/>
            <line own="bottom" target="bottom"/>
          </anchors>
        </ignition-gui>

        <sim_time>true</sim_time>
        <real_time>true</real_time>
        <real_time_factor>true</real_time_factor>
        <iterations>true</iterations>
      </plugin>

      <!-- Inspector -->
      <plugin filename="ComponentInspector" name="Component inspector">
        <ignition-gui>
          <property type="string" key="state">docked</property>
        </ignition-gui>
      </plugin>

      <!-- Entity tree -->
      <plugin filename="EntityTree" name="Entity tree">
        <ignition-gui>
          <property type="string" key="state">docked</property>
        </ignition-gui>
      </plugin>
    
      <plugin filename="ImageDisplay" name="Image Display 3">
        <ignition-gui>
          <title>RGBD: image</title>
          <property key="state" type="string">floating</property>
          <property type="double" key="width">350</property>
          <property type="double" key="height">315</property>
          <property type="double" key="y">320</property>

        </ignition-gui>
        <topic>rgbd_camera/image</topic>
        <topic_picker>false</topic_picker>
      </plugin>

      <plugin filename="ImageDisplay" name="Image Display 3">
        <ignition-gui>
          <title>RGBD: depth</title>
          <property key="state" type="string">docked</property>
        </ignition-gui>
        <topic>rgbd_camera/depth_image</topic>
        <topic_picker>false</topic_picker>
      </plugin>

      <plugin filename="MarkerManager" name="Marker manager">
        <ignition-gui>
          <property key="resizable" type="bool">false</property>
          <property key="width" type="double">5</property>
          <property key="height" type="double">5</property>
          <property key="state" type="string">floating</property>
          <property key="showTitleBar" type="bool">false</property>
        </ignition-gui>
      </plugin>

      <plugin filename="SelectEntities" name="Select Entities">
        <ignition-gui>
          <anchors target="Select entities">
            <line own="right" target="right"/>
            <line own="top" target="top"/>
          </anchors>
          <property key="resizable" type="bool">false</property>
          <property key="width" type="double">5</property>
          <property key="height" type="double">5</property>
          <property key="state" type="string">floating</property>
          <property key="showTitleBar" type="bool">false</property>
        </ignition-gui>
      </plugin>


      <plugin filename="VisualizationCapabilities" name="Visualization Capabilities">
        <ignition-gui>
          <property key="resizable" type="bool">false</property>
          <property key="width" type="double">5</property>
          <property key="height" type="double">5</property>
          <property key="state" type="string">floating</property>
          <property key="showTitleBar" type="bool">false</property>
        </ignition-gui>
      </plugin>

      <plugin filename="Spawn" name="Spawn Entities">
        <ignition-gui>
          <anchors target="Select entities">
            <line own="right" target="right"/>
            <line own="top" target="top"/>
          </anchors>
          <property key="resizable" type="bool">false</property>
          <property key="width" type="double">5</property>
          <property key="height" type="double">5</property>
          <property key="state" type="string">floating</property>
          <property key="showTitleBar" type="bool">false</property>
        </ignition-gui>
      </plugin>

      <!-- Insert simple shapes -->
      <plugin filename="Shapes" name="Shapes">
        <ignition-gui>
          <property key="resizable" type="bool">false</property>
          <property key="x" type="double">0</property>
          <property key="y" type="double">0</property>
          <property key="width" type="double">250</property>
          <property key="height" type="double">50</property>
          <property key="state" type="string">floating</property>
          <property key="showTitleBar" type="bool">false</property>
          <property key="cardBackground" type="string">#666666</property>
        </ignition-gui>
      </plugin>

      <!-- Insert lights -->
      <plugin filename="Lights" name="Lights">
        <ignition-gui>
          <property key="resizable" type="bool">false</property>
          <property key="x" type="double">250</property>
          <property key="y" type="double">0</property>
          <property key="width" type="double">150</property>
          <property key="height" type="double">50</property>
          <property key="state" type="string">floating</property>
          <property key="showTitleBar" type="bool">false</property>
          <property key="cardBackground" type="string">#666666</property>
        </ignition-gui>
      </plugin>

      <!-- Translate / rotate -->
      <plugin filename="TransformControl" name="Transform control">
        <ignition-gui>
          <property key="resizable" type="bool">false</property>
          <property key="x" type="double">0</property>
          <property key="y" type="double">50</property>
          <property key="width" type="double">250</property>
          <property key="height" type="double">50</property>
          <property key="state" type="string">floating</property>
          <property key="showTitleBar" type="bool">false</property>
          <property key="cardBackground" type="string">#777777</property>
        </ignition-gui>
        <legacy>false</legacy>
      </plugin>

      <!-- Screenshot -->
      <plugin filename="Screenshot" name="Screenshot">
        <ignition-gui>
          <property key="resizable" type="bool">false</property>
          <property key="x" type="double">250</property>
          <property key="y" type="double">50</property>
          <property key="width" type="double">50</property>
          <property key="height" type="double">50</property>
          <property key="state" type="string">floating</property>
          <property key="showTitleBar" type="bool">false</property>
          <property key="cardBackground" type="string">#777777</property>
        </ignition-gui>
      </plugin>

      <!-- Video recorder -->
      <plugin filename="VideoRecorder" name="VideoRecorder">
        <ignition-gui>
          <property key="resizable" type="bool">false</property>
          <property key="x" type="double">300</property>
          <property key="y" type="double">50</property>
          <property key="width" type="double">50</property>
          <property key="height" type="double">50</property>
          <property key="state" type="string">floating</property>
          <property key="showTitleBar" type="bool">false</property>
          <property key="cardBackground" type="string">#777777</property>
        </ignition-gui>
        <record_video>
          <use_sim_time>true</use_sim_time>
          <lockstep>true</lockstep>
          <bitrate>4000000</bitrate>
        </record_video>
        <legacy>false</legacy>
      </plugin>


      <plugin filename="ViewAngle" name="View angle">
        <ignition-gui>
          <property type="string" key="state">docked_collapsed</property>
        </ignition-gui>
        <legacy>false</legacy>
      </plugin>

    </gui>

    <light type="directional" name="sun">
      <cast_shadows>true</cast_shadows>
      <pose>0 0 10 0 0 0</pose>
      <diffuse>0.8 0.8 0.8 1</diffuse>
      <specular>0.2 0.2 0.2 1</specular>
      <attenuation>
        <range>1000</range>
        <constant>0.9</constant>
        <linear>0.01</linear>
        <quadratic>0.001</quadratic>
      </attenuation>
      <direction>-0.5 0.1 -0.9</direction>
    </light>

    <model name="rgbd_camera">

      <joint name="joint_world" type="fixed">
        <parent>world</parent>
        <child>rgbd_camera_lens</child>
      </joint>
      
      <link name="rgbd_camera_lens">
        <pose>1.0 0 1.2 0 1.5708 0</pose>

        <inertial>
          <mass>0.05</mass>
          <inertia>
<!-- 
            <ixx>0.000166667</ixx>
            <iyy>0.000166667</iyy>
            <izz>0.000166667</izz>
             -->
          </inertia>
        </inertial>

        <collision name="collision">
          <geometry>
            <box>
              <size>0.01 0.0936 0.0318</size>
            </box>
          </geometry>
        </collision>
        <visual name="visual">
          <geometry>
            <box>
              <size>0.01 0.0936 0.0318</size>
            </box>
          </geometry>
          <material>
            <ambient>0.85 0.85 0.85 1</ambient>
            <diffuse>0.85 0.85 0.85 1</diffuse>
            <specular>0.95 0.95 0.95 1</specular>
          </material>
        </visual>
        <sensor name="rgbd_camera" type="rgbd_camera">
          <camera>
            <horizontal_fov>1.9199</horizontal_fov>
            <image>
              <width>960</width>
              <height>600</height>
              <format>R8G8B8</format>
            </image>
            <clip>
              <near>0.01</near>
              <far>15</far>
            </clip>
            <depth_camera>
              <clip>
                <near>0.1</near>
                <far>8</far>
              </clip>
            </depth_camera>
          </camera>
          <always_on>1</always_on>
          <update_rate>60</update_rate>
          <visualize>true</visualize>
          <topic>rgbd_camera</topic>
          <enable_metrics>true</enable_metrics>
        </sensor>
      </link>
      
      <joint name="joint_camera" type="fixed">
        <parent>world</parent>
        <child>rgbd_camera_body</child>
      </joint>

      <link name="rgbd_camera_body">
        <pose>1.0 0 1.22 0 1.5708 0</pose>

        <inertial>
          <mass>0.101</mass>
        </inertial>

        <collision name="collision">
          <geometry>
            <box>
              <size>0.0324 0.0936 0.0318</size>
            </box>
          </geometry>
        </collision>

        <visual name="visual">
          <geometry>
            <box>
              <size>0.0324 0.0936 0.0318</size>
            </box>
          </geometry>
          <material>
            <ambient>0.0 0.0 0.0 1</ambient>
            <diffuse>0.0 0.0 0.0 1</diffuse>
            <specular>0.1 0.1 0.1 1</specular>
          </material>

        </visual>
      </link>
    </model>

    <!-- table -->
    <joint name="joint_table1" type="screw">
        <parent>world</parent>
        <child>table1</child> 
    </joint>

    <model name="table1">
      <static>true</static> 
      <pose>0.8 0 0.1 0 0 0</pose>
      <link name="table1_link">
        <inertial>
          <inertia>
            <ixx>1</ixx>
            <ixy>0</ixy>
            <ixz>0</ixz>
            <iyy>1</iyy>
            <iyz>0</iyz>
            <izz>1</izz>
          </inertia>
          <mass>1.0</mass>
        </inertial>
        <collision name="table1_collision">
          <geometry>
            <box>
              <size>0.7 2.0 0.2</size>
            </box>
          </geometry>
        </collision>
        <visual name="table1_visual">
          <geometry>
            <box>
              <size>0.7 2.0 0.2</size>
            </box>
          </geometry>
          <material>
            <ambient>0.6 0.4 0.2 1</ambient>
            <diffuse>0.8 0.5 0.3 1</diffuse>
            <specular>0.1 0.1 0.1 1</specular>
          </material>

        </visual>
      </link>
    </model>

    <!--box1-->
    <joint name="joint_box1" type="screw">
        <parent>world</parent>
        <child>markerbox1</child> 
    </joint>

    <include>
        <pose>1.0 0 0.25 0 0 0</pose>  
        <name>markerbox1</name>
        <uri>model://description/markerbox1.sdf</uri>
        
    </include>



    <!--box2-->
    <joint name="joint_box2" type="screw">
        <parent>world</parent>
        <child>markerbox2</child> 
    </joint>

    <include>
        <pose>0.7 0.5 0.25 0 0 0</pose>  
        <name>markerbox2</name>
        <uri>model://description/markerbox2.sdf</uri>
    </include>




    <!--box3-->
    <joint name="joint_box3" type="screw">
        <parent>world</parent>
        <child>markerbox3</child> 
    </joint>

    <include>
        <pose>0.7 -0.5 0.25 0 0 0</pose>  
        <name>markerbox3</name>        
        <uri>model://description/markerbox3.sdf</uri>
    </include>

  </world>
</sdf>
